Workbook

Sheet 보조기기 서비스 상세
A3: 2026년 | B3: 목표 | C3: 600 | E3: 건
A4: 날짜 (접수일 기준) | B4: 연번 | C4: 2026년 접수 | E4: 재접수 | F4: 접수번호 | H4: 이름 | I4: 생년월일 | J4: 연령 (입력금지자동완성) | K4: 성별 (입력금지자동완성) | L4: 거주지 (시군구) -필수 | M4: 주 장애유형 | N4: 서비스 분류 | O4: 제품명 | P4: 픔목고시 (자동완성) | Q4: 서비스 제공 내용 (서비스 상세 내용 작성) | R4: 서비스 영역 (자동완성) | S4: 보조기기센터 사업 | AJ4: 서비스진행상황
C5: 그외 (09-25) | D5: 2026 | F5: 년도 | G5: 번호 | S5: 보조기기 상담 | U5: 체험지원 | V5: 보조기기 맞춤형 지원 | Y5: 교육 | Z5: 기타사업 | AA5: 주요 사업 외 | AB5: 재원연계 | AE5: 재원확보 | AF5: 사후관리 지원사업 | AI5: 모니 터링 | AJ5: 의뢰 구분 | AK5: 서비스 제공 | AN5: 종결 여부 | AO5: 담당자
S6: 상담 | T6: 평가 | U6: 보조 기기 사용 체험 (구. 시험적용) | V6: 대여 | W6: 맞춤 제작 지원 | X6: 교부 사업 맞춤형 평가 지원 | Y6: 이용자 교육 | Z6: 기타 사업 | AA6: 정보 제공/ 교육 및 훈련 | AB6: 공적 급여 | AC6: 민간 급여 | AD6: 자부담 | AE6: 재원 확보시 체크 | AF6: 점검 및 수리 | AG6: 소독 및 세척 | AH6: 재사용 | AK6: 유선 | AL6: 내방 | AM6: 방문 (출장)
C7: =SUM(C8+E8) -> 177
C8: =SUM(C9+D9) -> 129 | E8: =SUM(E9) -> 48
B9: 합계 | C9: =COUNTA(C10:C1000) -> 69 | D9: =COUNTA(D10:D1000) -> 60 | E9: =COUNTA(E10:E1000) -> 48 | R9: - | S9: =COUNTA(S10:S5001) -> 171 | T9: =COUNTA(T10:T5001) -> 171 | U9: =COUNTA(U10:U100001) -> 9 | V9: =COUNTA(V10:V100001) -> 21 | W9: =COUNTA(W10:W5001) -> 28 | X9: =COUNTA(X10:X5001) -> 73 | Y9: =COUNTA(Y10:Y5001) -> 0 | Z9: =COUNTA(Z10:Z5001) -> 0 | AA9: =COUNTA(AA10:AA5001) -> 28 | AB9: =COUNTA(AB10:AB5001) -> 0 | AC9: =COUNTA(AC10:AC5001) -> 24 | AD9: =COUNTA(AD10:AD500) -> 0 | AE9: =COUNTA(AE10:AE5001) -> 0 | AF9: =COUNTA(AF10:AF5001) -> 0 | AG9: =COUNTA(AG10:AG5001) -> 13 | AH9: =COUNTA(AH10:AH5001) -> 3 | AI9: =COUNTA(AI10:AI5001) -> 0 | AJ9: =COUNTA(AJ10:AJ5001) -> 172 | AK9: =COUNTA(AK10:AK5001) -> 33 | AL9: =COUNTA(AL10:AL5001) -> 37 | ... AN9: =COUNTA(AN10:AN5001) -> 175 | AP9: 연락처 | AQ9: 주소
A10: 2026-01-02 | B10: 1 | C10: 2026 | D10: 1 | E10: 35 | G10: 완료 | H10: 김도원 | I10: 2013-08-12 | J10: 남 | L10: 춘천시 | M10: 뇌병변 | N10: 정보제공(주요사업 외) | O10: 오터목욕의자 | P10: 목욕의자 | Q10: 신용카드사회공헌재단 민간지원사업 신청 | R10: ADL | AA10: ✓ | AJ10: 지역 | AN10: 종결 | AO10: 양하나
A11: 2026-01-07 | B11: 2 | C11: 2026 | D11: 1 | E11: 88 | G11: 완료 | H11: 한효리 | I11: 2020-06-11 | J11: 여 | L11: 원주시 | M11: 지체 | N11: 정보제공(주요사업 외) | O11: 모션큐 이보크 | P11: 침대 및 탈착식 침대 판/전동조절식 매트리스 지지단 (전동 침대) | Q11: 신용카드사회공헌재단 민간지원사업 신청 | R11: ADL | AA11: ✓ | AJ11: 지역 | AN11: 종결 | AO11: 양하나
A12: 2026-01-13 | B12: 3 | C12: 2026 | D12: 1 | E12: 2 | G12: 완료 | H12: 조유나 | I12: 2019-12-03 | J12: 여 | L12: 춘천시 | M12: 뇌병변 | N12: 정보제공(주요사업 외) | O12: 파이퍼 유모차형휠체어 | P12: 유모차형 이동보조기기 | Q12: 신용카드사회공헌재단 민간지원사업 신청 | R12: WC | AA12: ✓ | AJ12: 지역 | AN12: 종결 | AO12: 양하나
A13: 2026-01-14 | B13: 4 | C13: 2026 | D13: 1 | E13: 1 | G13: 미정 | H13: 김강민 | I13: 2016-10-04 | J13: 남 | L13: 춘천시 | M13: 지체 | N13: 대여 | O13: 오터 목욕의자(중) | P13: 목욕 의자 | Q13: 오터 목욕의자 / 6개월 | R13: ADL | V13: ✓ | AJ13: 지역 | AO13: 심채연
A14: 2026-01-15 | B14: 5 | C14: 2026 | D14: 1 | E14: 31 | G14: 미정 | H14: 김경아 | I14: 1976-09-13 | J14: 여 | L14: 춘천시 | M14: 뇌병변 | N14: 대여 | O14: 지팡이 | P14: 지팡이 | Q14: 지팡이 / 6개월 | R14: WC | V14: ✓ | AJ14: 지역 | AO14: 심채연
A15: 2026-01-19 | B15: 6 | C15: 2026 | D15: 1 | E15: 133 | G15: 완료 | H15: 장상윤 | I15: 1957-09-06 | J15: 남 | L15: 춘천시 | M15: 지체 | N15: 맞춤 제작 지원 | O15: 조이스틱 | P15: -(휠체어 액세서리) | Q15: 전동휠체어 조이스틱 | R15: WC | W15: ✓ | AJ15: 지역 | AN15: 종결 | AO15: 송근필
A16: 2026-01-20 | B16: 7 | C16: 2026 | D16: 1 | E16: 1 | G16: 미정 | H16: 김애라 | I16: 1962-10-27 | J16: 여 | L16: 춘천시 | M16: 청각 | N16: 교부사업 맞춤형 평가 | O16: 진동시계 | P16: 진동시계 | Q16: 진동시계/ 적합 | R16: S | X16: ✓ | AJ16: 연계 | AO16: 심채연
A17: 2026-01-20 | B17: 8 | C17: 2026 | D17: 1 | E17: 166 | G17: 완료 | H17: 조선희 | I17: 1966-04-24 | J17: 여 | L17: 춘천시 | M17: 뇌병변 | N17: 교부사업 맞춤형 평가 | O17: 전동침대 | P17: 침대 및 탈착식 침대 판/전동조절식 매트리스 지지단 (전동 침대) | Q17: 전동침대/취소 | R17: ADL | X17: ✓ | AJ17: 연계 | AN17: 종결 | AO17: 양하나
A18: 2026-01-20 | B18: 9 | C18: 2026 | D18: 1 | E18: 3 | G18: 완료 | H18: 김태희 | I18: 2015-10-11 | J18: 여 | L18: 원주시 | M18: 뇌병변 | N18: 정보제공(주요사업 외) | O18: 캐롯카시트 | P18: 차량 내 착석을 위한 좌석과 방석, 액세서리, 개조용품 | Q18: 신용카드사회공헌재단 민간지원사업 신청 | R18: AM | AA18: ✓ | AJ18: 지역 | AN18: 종결 | AO18: 양하나
A19: 2026-01-21 | B19: 10 | C19: 2026 | D19: 1 | E19: 15 | G19: 미정 | H19: 이찬섭 | I19: 1961-10-16 | J19: 남 | L19: 춘천시 | M19: 지체 | N19: 대여 | O19: 수동휠체어 | P19: 일반형 수동휠체어(양 손 추진 휠체어) | Q19: 수동휠체어 / 6개월 | R19: WC | V19: ✓ | AJ19: 지역 | AO19: 심채연
A20: 2026-01-21 | B20: 11 | C20: 2026 | D20: 1 | E20: 248 | G20: 완료 | H20: 박동재 | I20: 1994-03-07 | J20: 남 | L20: 춘천시 | M20: 지체 | N20: 재사용 | O20: 수동휠체어 | P20: 일반형 수동휠체어(양 손 추진 휠체어) | Q20: 수동휠체어 재사용 지원 | R20: WC | AH20: ✓ | AJ20: 지역 | AN20: 종결 | AO20: 심채연
A21: 2026-01-22 | B21: 12 | C21: 2026 | D21: 1 | E21: 3 | G21: 완료 | H21: 김태희 | I21: 2025-10-11 | J21: 여 | L21: 원주시 | M21: 뇌병변 | N21: 정보제공(주요사업 외) | O21: 캐롯카시트 | P21: 차량 내 착석을 위한 좌석과 방석, 액세서리, 개조용품 | Q21: EY한영 장애아동청소년 민간지원사업 신청 | R21: AM | AA21: ✓ | AJ21: 지역 | AN21: 종결 | AO21: 양하나
A22: 2026-01-22 | B22: 13 | C22: 2026 | D22: 1 | E22: 47 | G22: 완료 | H22: 신인준 | I22: 1966-10-13 | J22: 남 | L22: 춘천시 | M22: 지체 | N22: 재사용 | O22: 수동휠체어 | P22: 일반형 수동휠체어(양 손 추진 휠체어) | Q22: 수동휠체어 재사용 지원 | R22: WC | AH22: ✓ | AJ22: 지역 | AN22: 종결 | AO22: 심채연
A23: 2026-01-22 | B23: 14 | C23: 2026 | D23: 1 | E23: 3 | G23: 완료 | H23: 김태희 | I23: 2015-10-11 | J23: 여 | L23: 원주시 | M23: 뇌병변 | N23: 정보제공(주요사업 외) | O23: 캐롯카시트 | P23: 차량 내 착석을 위한 좌석과 방석, 액세서리, 개조용품 | Q23: EY한영 민간지원사업 신청 | R23: AM | AA23: ✓ | AJ23: 지역 | AN23: 종결 | AO23: 양하나
A24: 2026-01-24 | B24: 15 | C24: 2026 | D24: 1 | E24: 125 | G24: 미정 | H24: 안홍태 | I24: 1967-04-21 | J24: 남 | L24: 강릉시 | M24: 뇌병변 | N24: 대여 | O24: 수동휠체어 | P24: 일반형 수동휠체어(양 손 추진 휠체어) | Q24: 수동휠체어 / 6개월 | R24: WC | V24: ✓ | AJ24: 지역 | AO24: 심채연
A25: 2026-01-28 | B25: 16 | C25: 2026 | D25: 1 | E25: 137 | G25: 미정 | H25: 이근수 | I25: 1968-03-01 | J25: 남 | L25: 춘천시 | M25: 뇌병변 | N25: 대여 | O25: 수동휠체어 | P25: 일반형 수동휠체어(양 손 추진 휠체어) | Q25: 수동휠체어 / 6개월 | R25: WC | V25: ✓ | AJ25: 지역 | AO25: 심채연
A26: 2026-01-30 | B26: 17 | C26: 2026 | D26: 1 | E26: 210 | G26: 완료 | H26: 전기택 | I26: 1964-03-04 | J26: 남 | L26: 춘천시 | M26: 뇌병변 | N26: 교부사업 맞춤형 평가 | O26: 목욕의자 | P26: 목욕의자 | Q26: 목욕의자/적합 | R26: ADL | X26: ✓ | AJ26: 연계 | AN26: 종결 | AO26: 심채연
A27: 2026-01-30 | B27: 18 | C27: 2026 | D27: 1 | E27: 10 | G27: 완료 | H27: 박호연 | I27: 1979-04-27 | J27: 남 | L27: 춘천시 | M27: 뇌병변 | N27: 교부사업 맞춤형 평가 | O27: 목욕의자 | P27: 목욕의자 | Q27: 목욕의자/적합 | R27: ADL | X27: ✓ | AJ27: 연계 | AN27: 종결 | AO27: 양하나
A28: 2026-01-30 | B28: 19 | C28: 2026 | D28: 1 | E28: 127 | G28: 완료 | H28: 박영희 | I28: 1957-03-11 | J28: 여 | L28: 춘천시 | M28: 뇌병변 | N28: 재사용 | O28: 수동휠체어 | P28: 일반형 수동휠체어(양 손 추진 휠체어) | Q28: 수동휠체어 재사용 지원 | R28: WC | AH28: ✓ | AJ28: 지역 | AN28: 종결 | AO28: 심채연
A29: 2026-02-01 | B29: 20 | C29: 2026 | D29: 2 | E29: 15 | G29: 미정 | H29: 김다영 | I29: 2004-02-09 | J29: 여 | L29: 철원군 | M29: 뇌병변 | N29: 대여 | O29: 장애인용유모차 | P29: 유모차형 이동보조기기 | Q29: 빙고 / 6개월 | R29: WC | V29: ✓ | AJ29: 지역 | AO29: 심채연
A30: 2026-02-02 | B30: 21 | C30: 2026 | D30: 2 | E30: 101 | G30: 미정 | H30: 권춘자 | I30: 1937-07-02 | J30: 여 | L30: 춘천시 | M30: 장기요양 | N30: 대여 | O30: ASH-201 | P30: 고정형 손잡이와 핸드그립 | Q30: ASH-201 / 6개월 | R30: ADL | V30: ✓ | AJ30: 지역 | AO30: 심채연
A31: 2026-02-03 | B31: 22 | C31: 2026 | D31: 2 | E31: 176 | G31: 완료 | H31: 조재명 | I31: 1951-12-09 | J31: 여 | L31: 홍천군 | M31: 시각 | N31: 교부사업 맞춤형 평가 | O31: 리보3S | P31: 키보드 | Q31: 리보3S / 적합 | R31: CA | X31: ✓ | AJ31: 연계 | AN31: 종결 | AO31: 양하나
A32: 2026-02-03 | B32: 23 | C32: 2026 | D32: 2 | E32: 24 | G32: 미정 | H32: 최윤석 | I32: 1973-04-13 | J32: 남 | L32: 강릉시 | M32: 지체 | N32: 맞춤 제작 지원 | O32: 랩보드 | P32: 휠체어용 무릎받침대 | Q32: 랩보드(취소) | R32: SP | W32: ✓ | AJ32: 지역 | AO32: 송근필
A33: 2026-02-03 | B33: 24 | C33: 2026 | D33: 2 | E33: 102 | G33: 미정 | H33: 윤성광 | I33: 1993-05-05 | J33: 남 | L33: 춘천시 | M33: 지체 | N33: 맞춤 제작 지원 | O33: 보치아경기용세트 | P33: 팀 구기 스포츠용 보조기기 | Q33: 보치아용 푸셔 | R33: L | W33: ✓ | AJ33: 지역 | AO33: 송근필
A34: 2026-02-03 | B34: 25 | C34: 2026 | D34: 2 | E34: 25 | G34: 미정 | H34: 김시영 | J34: 여 | L34: 춘천시 | M34: 지체 | N34: 맞춤 제작 지원 | O34: 랩보드 | P34: 휠체어용 무릎받침대 | R34: SP | W34: ✓ | AJ34: 지역 | AO34: 송근필
A35: 2026-02-04 | B35: 26 | C35: 2026 | D35: 2 | E35: 4 | G35: 미정 | H35: 김종길 | I35: 1958-06-05 | J35: 남 | L35: 춘천시 | M35: 지체 | N35: 맞춤 제작 지원 | O35: 휠체어용 우산거치대 | P35: -(휠체어 액세서리) | Q35: 수동휠체어 우산꽃이 | R35: WC | W35: ✓ | AJ35: 지역 | AO35: 양하나
A36: 2026-02-05 | B36: 27 | C36: 2026 | D36: 2 | E36: 5 | G36: 미정 | H36: 이용기 | I36: 1981-09-11 | J36: 남 | L36: 속초시 | M36: 뇌병변 | N36: 교부사업 맞춤형 평가 | O36: 안전손잡이 | P36: 고정형 손잡이와 핸드그립 | Q36: 안전손잡이 / 취소 | R36: ADL | X36: ✓ | AJ36: 연계 | AO36: 양하나
A37: 2026-02-05 | B37: 28 | C37: 2026 | D37: 2 | E37: 242 | G37: 완료 | H37: 김혜경 | I37: 1975-04-13 | J37: 여 | L37: 강릉시 | M37: 뇌병변 | N37: 교부사업 맞춤형 평가 | O37: AFM-06 | P37: 목욕용 미끄럼 방지용품 | Q37: AFM-06 / 적합 | R37: ADL | X37: ✓ | AJ37: 연계 | AN37: 종결 | AO37: 양하나
A38: 2026-02-05 | B38: 29 | C38: 2026 | D38: 2 | E38: 163 | G38: 완료 | H38: 박광종 | I38: 1964-02-15 | J38: 남 | L38: 강릉시 | M38: 뇌병변 | N38: 교부사업 맞춤형 평가 | O38: DGP-0002 | P38: 고정형 손잡이와 핸드그립 | Q38: DGP-0002 / 변경 | R38: ADL | X38: ✓ | AJ38: 연계 | AN38: 종결 | AO38: 양하나
A39: 2026-02-05 | B39: 30 | C39: 2026 | D39: 2 | E39: 12 | G39: 완료 | H39: 조지영 | I39: 1977-01-11 | J39: 여 | L39: 강릉시 | M39: 지체 | N39: 교부사업 맞춤형 평가 | O39: 유모차형 이동보조기기 | P39: 유모차형 이동보조기기 | Q39: 유모차형이동보조기기 / 부적합 | R39: WC | X39: ✓ | AJ39: 연계 | AN39: 종결 | AO39: 양하나
A40: 2026-02-09 | B40: 31 | C40: 2026 | D40: 2 | E40: 220 | G40: 미정 | H40: 이상기 | I40: 1957-09-09 | J40: 남 | L40: 춘천시 | M40: 지체 | N40: 맞춤 제작 지원 | O40: 랩보드 | P40: 휠체어용 무릎받침대 | Q40: 수동휠체어 랩보드 | R40: SP | W40: ✓ | AJ40: 지역 | AO40: 송근필
A41: 2026-02-09 | B41: 32 | C41: 2026 | D41: 2 | E41: 11 | G41: 미정 | H41: 이시훈 | I41: 2007-12-04 | J41: 남 | L41: 춘천시 | M41: 뇌병변 | N41: 대여 | O41: 한손키보드 | P41: 키보드 | Q41: 한손키보드 | R41: CA | V41: ✓ | AJ41: 지역 | AO41: 송근필
A42: 2026-02-12 | B42: 33 | C42: 2026 | D42: 2 | E42: 6 | G42: 완료 | H42: 이유영 | I42: 1959-08-26 | J42: 남 | L42: 삼척시 | M42: 뇌병변 | N42: 교부사업 맞춤형 평가 | O42: 소변수집장치 | P42: 소변 수집 장치 | Q42: 소변수집장치 / 적합 | R42: ADL | X42: ✓ | AJ42: 연계 | AN42: 종결 | AO42: 심채연
...

Sheet 제품명
A1: ㅋ | B1: 사업명 | C1: 대분류 | D1: 중분류 | E1: 소분류 | F1: 보조기기 명(기관에서 받은거)
A2: 전동스쿠터 우비 G2 | B2: 기타(미등록 보조기기) | E2: -(의류 및 신발)
A3: 테이블 작업용 전동 서랍 1800×900×700 1200 | B3: 보조공학기기지급사업 | C3: 작업 활동 및 취업 참여용 보조기기 | D3: 작업장내 가구 및 비품요소 | E3: 작업 책상 | F3: 테이블 작업용 전동 서랍 1800×900×700 1200
A4: #300 | B4: 기타(미등록 보조기기) | E4: -(양팔 조작형 보행용 보조기기)
A5: 2.OAL | B5: 장애인보조기기 지급사업(건강보험, 의료급여) | C5: 개인 가동성 및 수송과 관련된 활동 및 참여용 보조기기 | D5: 수동휠체어 | E5: 일반형 수동휠체어(양 손 추진 휠체어) | F5: 수동휠체어-활동형
A6: 24인치 멀티터치모니터/TV | B6: 정보통신보조기기보급사업 | C6: 의사소통 및 정보관리용 보조기기 | D6: 출력 장치 | E6: 시각 디스플레이 | F6: 터치모니터
A7: 24인치 멀티확대 터치모니터 LED TV | B7: 정보통신보조기기보급사업 | C7: 의사소통 및 정보관리용 보조기기 | D7: 출력 장치 | E7: 시각 디스플레이 | F7: 터치모니터
A8: 24인치 모니터 LED TV | B8: 정보통신보조기기보급사업 | C8: 의사소통 및 정보관리용 보조기기 | D8: 출력 장치 | E8: 시각 디스플레이 | F8: 터치모니터
A9: 24인치 화면 확대 터치 모니터 | B9: 정보통신보조기기보급사업 | C9: 의사소통 및 정보관리용 보조기기 | D9: 출력 장치 | E9: 시각 디스플레이 | F9: 터치모니터
A10: 24인치멀티확대터치모니터 | B10: 기타(미등록 보조기기) | E10: 시각 디스플레이
A11: 24인치멀티확대터치모니터TV | B11: 보조공학기기지급사업 | C11: 의사소통 및 정보관리용 보조기기 | D11: 출력 장치 | E11: 시각 디스플레이 | F11: 24인치멀티확대터치모니터TV(2023년)
A12: 24인치일체형터치모니터 | B12: 보조공학기기지급사업 | C12: 의사소통 및 정보관리용 보조기기 | D12: 출력 장치 | E12: 시각 디스플레이 | F12: 24인치일체형터치모니터(2023년)
A13: 24인치정전식터치모니터(엘피케이에스) | B13: 보조공학기기지급사업 | C13: 의사소통 및 정보관리용 보조기기 | D13: 출력 장치 | E13: 시각 디스플레이 | F13: 24인치정전식터치모니터(엘피케이에스)(2022년)
A14: 27인치 멀티터치모니터 | B14: 정보통신보조기기보급사업 | C14: 의사소통 및 정보관리용 보조기기 | D14: 출력 장치 | E14: 시각 디스플레이 | F14: 터치모니터
A15: 27인치 정전식 터치모니터 | B15: 정보통신보조기기보급사업 | C15: 의사소통 및 정보관리용 보조기기 | D15: 출력 장치 | E15: 시각 디스플레이 | F15: 터치모니터 | I15: ㄹ
A16: 27인치4K거치형모니터 | B16: 보조공학기기지급사업 | C16: 의사소통 및 정보관리용 보조기기 | D16: 출력 장치 | E16: 시각 디스플레이 | F16: 27인치4K거치형모니터(2023년)
A17: 27인치IR터치모니터 | B17: 보조공학기기지급사업 | C17: 의사소통 및 정보관리용 보조기기 | D17: 출력 장치 | E17: 시각 디스플레이 | F17: 27인치IR터치모니터(2023년)
A18: 27인치멀티확대터치모니터 | B18: 기타(미등록 보조기기) | E18: 시각 디스플레이
A19: 27인치멀티확대터치모니터TV | B19: 보조공학기기지급사업 | C19: 의사소통 및 정보관리용 보조기기 | D19: 출력 장치 | E19: 시각 디스플레이 | F19: 27인치멀티확대터치모니터TV(2023년)
A20: 27인치화면확대터치모니터 | B20: 보조공학기기지급사업 | C20: 의사소통 및 정보관리용 보조기기 | D20: 출력 장치 | E20: 시각 디스플레이 | F20: 27인치화면확대터치모니터(2023년)
A21: 27인치화면확대터치모니터 | B21: 정보통신보조기기보급사업 | C21: 의사소통 및 정보관리용 보조기기 | D21: 출력 장치 | E21: 시각 디스플레이 | F21: 터치모니터
A22: 2GX | B22: 장애인보조기기 지급사업(건강보험, 의료급여) | C22: 개인 가동성 및 수송과 관련된 활동 및 참여용 보조기기 | D22: 수동휠체어 | E22: 일반형 수동휠체어(양 손 추진 휠체어) | F22: ㄹ
A23: 300/라벤다 | B23: 기타(미등록 보조기기) | E23: -(양팔 조작형 보행용 보조기기)
A24: 32인치 IR 터치모니터 | B24: 보조공학기기지급사업 | C24: 의사소통 및 정보관리용 보조기기 | D24: 출력 장치 | E24: 시각 디스플레이 | F24: 32인치IR터치모니터(2023년)
A25: 32인치 IR 터치모니터 | B25: 정보통신보조기기보급사업 | C25: 의사소통 및 정보관리용 보조기기 | D25: 출력 장치 | E25: 시각 디스플레이 | F25: 터치모니터
A26: 32인치4K모니터 | B26: 보조공학기기지급사업 | C26: 의사소통 및 정보관리용 보조기기 | D26: 출력 장치 | E26: 시각 디스플레이 | F26: 32인치4K모니터(2022년)
A27: 32인치IR모니터 | B27: 보조공학기기지급사업 | C27: 의사소통 및 정보관리용 보조기기 | D27: 출력 장치 | E27: 시각 디스플레이 | F27: 32인치IR모니터(2022년)
A28: 32인치모니터 | B28: 보조공학기기지급사업 | C28: 의사소통 및 정보관리용 보조기기 | D28: 출력 장치 | E28: 시각 디스플레이 | F28: 32인치모니터(2022년)
A29: 32인치일체형LED모니터 | B29: 보조공학기기지급사업 | C29: 의사소통 및 정보관리용 보조기기 | D29: 출력 장치 | E29: 시각 디스플레이 | F29: 32인치일체형LED모니터(2023년)
A30: 360 컵홀더 | B30: 기타(미등록 보조기기) | E30: -(휠체어 액세서리)
A31: 3D-1 | B31: 장애인보조기기 지급사업(건강보험, 의료급여) | C31: 신경근골격계 기능 또는 움직임 관련 기능을 지지하기 위하여 그리고 해부학적 구조를 대체하기 위하여 신체에 부착되는 보조기기 | D31: 기타 의지 | E31: 의안 | F31: 의안
A32: 3GTQSP-3GTQSPR2 | B32: 장애인보조기기 지급사업(건강보험, 의료급여) | C32: 개인 가동성 및 수송과 관련된 활동 및 참여용 보조기기 | D32: 동력 구동 휠체어 | E32: 전동 휠체어 (전동 조향식 전동 휠체어) | F32: 전동 휠체어
A33: 3STAR | B33: 보조공학기기지급사업 | C33: 의사소통 및 정보관리용 보조기기 | D33: 읽기, 쓰기, 그리기 보조기기 | E33: DAISY 플레이어 및 전자책 리더 | F33: 3STAR(N2021년)
A34: 3STAR | B34: 기타(미등록 보조기기) | E34: DAISY 플레이어 및 전자책 리더
A35: 3STAR 2 | B35: 기타(미등록 보조기기) | E35: DAISY 플레이어 및 전자책 리더
A36: 3단 리프트 전동 책상 | B36: 기타(미등록 보조기기) | E36: 독서용 탁자, 책상 및 기립형 책상
A37: 3모터 전동침대(HBA-333) | B37: 기타(미등록 보조기기) | E37: 침대 및 탈착식 침대 판/전동조절식 매트리스 지지단 (전동 침대)
A38: 3점압 모듈러 이너 | B38: 장애인보조기기 지급사업(건강보험, 의료급여) | C38: 인공적 실내외 활동 지지용 가구, 설비 및 기타 보조기기 | D38: 앉기 자세유지용 장치 | E38: 자세보조용구 | F38: 자세보조용구
A39: 4081WS | B39: 장애인보조기기 지급사업(건강보험, 의료급여) | C39: 개인 가동성 및 수송과 관련된 활동 및 참여용 보조기기 | D39: 양팔 조작형 보행용 보조기기 | E39: 롤레이터(보행차) | F39: 전방보행차
A40: 4DM-002 | B40: 노인장기요양보험 복지용구 지급사업 | C40: 인공적 실내외 활동 지지용 가구, 설비 및 기타 보조기기 | D40: 주택 및 기타 토지용 안전 설비 | E40: 미끄럼 방지용품 | F40: 미끄럼 방지용품
...

Sheet 품목명
B1: 품목고시 명칭에 따른 보조기기 영역
B3: 연번 | C3: 품목고시 명칭 | D3: 보조기기 영역
B4: 1 | C4: (등-)허리-엉치-엉덩-무릎-발목-발 보조기 | D4: ADL
B5: 2 | C5: 2인 이상용 2륜 자전거, 3륜 자전거, 4륜 자전거 | D5: L
B6: 3 | C6: DAISY 플레이어 및 전자책 리더 | D6: S
B7: 4 | C7: OCR 장치 및 OCR 소프트웨어 (문자판독기) | D7: S
B8: 5 | C8: 가발 | D8: ADL
B9: 6 | C9: 가스 공급용 안전밸브 | D9: EC
B10: 7 | C10: 가슴 보형물 | D10: ADL
B11: 8 | C11: 가위 | D11: ADL
B12: 9 | C12: 각도 측정용 보조기기 및 도구 | D12: ADL
B13: 10 | C13: 간이 리프트(호이스트용 신체지지 장치) | D13: ADL
B14: 11 | C14: 간이변기(변기 좌석) | D14: ADL
B15: 12 | C15: 감각 통합 훈련용 보조 기기 | D15: ADL
... B782: 779 | C782: 흰 지팡이와 심벌 지팡이용 액세서리 | D782: S
B783: 품목고시외 | C783: -(양팔 조작형 보행용 보조기기) | D783: WC
B784: 품목고시외 | C784: -(시각보조기기) | D784: S
B785: 품목고시외 | C785: -(의류 및 신발) | D785: ADL
B786: 품목고시외 | C786: -(휠체어 액세서리) | D786: WC
B787: 품목고시외 | C787: -(직업 평가 및 직업 훈련용 보조기기) | D787: ADL
B788: 품목고시외 | C788: -다리보조기 | D788: ADL
B789: 품목고시외 | C789: -척추 및 머리보조기 | D789: ADL
B790: 품목고시외 | C790: -팔보조기 | D790: ADL
B791: 품목고시외 | C791: -(동력 구동 휠체어) | D791: WC
