Workbook

Sheet 2026
B1: <안내 사항> 1. 향후 각 보조기기센터 콜센터 상담일지 내용 취합 시 개인정보보호법 해당되는 의뢰인 성명, 의뢰인 연락처에 해당되는 항목은 제외하여 회신 * 의뢰인 성명, 의뢰인 연락처 : 개인을 알아볼 수 있는 정보(해당 정보만으로는 특정 개인을 알아볼 수 없더라도 다른 정보와 쉽게 결합하여 알아볼 수 있는 것을 포함함) 2. 엑셀시트 항목 중 진한글씨항목(연번, 상담일, 의뢰외 유형, 상담내용(질문유형, 질문내용, 답볍))은 필수항목이므로 반드시 입력, 이외 나머지는 선택사항임 3. 상담내용 작성 시, 반드시 질문유형(공적급여, 민간급여, 보조기기, 사례연계, 기타)에 한가지는 입력 후 질문내용 및 답변 입력 필요
B4: 일반정보 | M4: 상담내용 | T4: 상담자
B5: 연번 | C5: 상담일 | D5: 의뢰인 성명 | E5: 의뢰인 지역 또는 소속 | F5: 의뢰인 연락처 | G5: 의뢰인 유형 | H5: 대상자 성명 | I5: 대상자 성별 | J5: 대상자 장애유형 | K5: 대상자 장애정도 | L5: 대상자 경제상황 | M5: 질문 유형 | R5: 질문내용 | S5: 답변 (상담에 따른 조치사항 등)
M6: 공적급여 | N6: 민간급여 | O6: 보조기기 | P6: 사례연계 | Q6: 기타
M7: =COUNTA(M9:M283) -> 11 | N7: =COUNTA(N9:N283) -> 9 | O7: =COUNTA(O9:O283) -> 33 | P7: =COUNTA(P9:P283) -> 1 | Q7: =COUNTA(Q9:Q283) -> 4
B8: =COUNTA(B9:B283) -> 185 | C8: =COUNTA(C9:C283) -> 72 | G8: =COUNTA(G9:G283) -> 70 | M8: =SUM(M7:Q7) -> 58
B9: =ROW()-8 -> 1 | C9: 46029 | D9: 김인욱 | E9: 강릉 | F9: 010-3718-8962 | G9: 장애 당사자 | O9: 대여 | R9: 안구마우스 반납 관련 문의 | S9: 현재 출장 방문이 어려운 상황으로, 추후 출장 일정이 확정되는 대로 연락드린 후 보조기기 수거를 진행할 예정임을 안내함. | T9: 심채연
B10: =ROW()-8 -> 2 | C10: 45664 | E10: 동해시장애요양원 | F10: 070-4259-4701 010-3487-3471 | G10: 유관기관 종사자 | O10: 대여 | R10: 바디서포트 대여 문의 | S10: 현재 대여 사업이 시작되지 않아, 대여 사업이 시작하면 사전에 연락드릴 수 있도록 보조기기 대기명단 안내와 등록과정을 도와드림. | T10: 심채연
B11: =ROW()-8 -> 3 | C11: 46029 | E11: 원주 발달장애인 통합돌봄서비스 제공기관 | F11: 010-3221-6143 | G11: 유관기관 종사자 | O11: 대여 | R11: 휠체어 침상을 이동할 수 있는 보조기기에 대한 정보 문의 | S11: 이동식 전동 리프트, 슬라이딩보드 및 시트 정보를 안내드림. | T11: 심채연
B12: =ROW()-8 -> 4 | C12: 46031 | E12: 원주 | F12: 010-8800-7532 | G12: 보호자 및 지인 | R12: 장애인등록은 되어 있으시고 기초생활수급자이고 보조기기 지원사업에 대해서 안내 | S12: 교부사업에 대해서 안내해드렸음. | T12: 이창하
B13: =ROW()-8 -> 5 | C13: 46034 | D13: 전기택 | E13: 춘천 | F13: 010-7368-1174 | G13: 보호자 및 지인 | R13: 보조기기 교부사업 신청 안내 및 건강보험공단 보조기기 지원사업 안내에 대한 문의를 주셨음. | S13: 건강보험공단 보조기기 지원사업 연락처 안내 및 교부사업 신청 안내 | T13: 이창하
B14: =ROW()-8 -> 6 | C14: 46037 | E14: 원주 | F14: 010-2240-8667 | G14: 보호자 및 지인 | H14: 김지원 | I14: 남 | J14: 자폐 | K14: 중증 | O14: 대여 | R14: 마이토키 스마트 대여 관련 문의 | S14: 현재 발생되고 있는 문제(상징물 저장 안됨)에 대해 해결 방안을 안내드렸음. | T14: 심채연
B15: =ROW()-8 -> 7 | C15: 46037 | E15: 원주 | F15: 010-2018-0313 | G15: 보호자 및 지인 | H15: 한윤주 | I15: 여 | J15: 지체 | O15: 대여 | R15: 좌석형 계단식 리프트 대여 요청 | S15: 현재 대여나간 품목이기 때문에 당장은 대여가 불가능하다는 점을 안내드렸고, 추후 반납 시 연락드릴 수 있도록 보조기기 대기 명단 안내와 등록과정을 도와드림. | T15: 심채연
B16: =ROW()-8 -> 8 | C16: 46038 | D16: 김희진 | E16: 철원 | F16: 010-8654-4730 | G16: 장애 당사자 | O16: 대여 | R16: 한소네 대여 관련 문의 | S16: 대여 대기관리 대장 확인 결과, 대여는 가능하지만 현재 당장은 대여가 불가능하고, 추후 대여 사업 시작 시 다시 연락드리기로 함. | T16: 심채연
B17: =ROW()-8 -> 9 | C17: 46042 | E17: 원주 | F17: 033-737-5985 | G17: 시군구(및 읍면동) 담당자 | M17: 신청 | R17: 장애인 보조기기 교부사업 신청 방법, 교부 가능 품목 확인 | S17: 교부사업 신청 과정 및 방법 안내, 보조기기 품목(휠체어 액세서리)에 대해 안내 드림. | T17: 양하나
B18: =ROW()-8 -> 10 | C18: 46043 | D18: 방시우 | E18: 영월 | F18: 010-8711-9062 | G18: 보호자 및 지인 | O18: 대여 | R18: 아동용 보행보조기 추천 | S18: 아동용 보행보조기 추천을 해드렸음. | T18: 이창하
B19: =ROW()-8 -> 11 | C19: 46044 | D19: 김광희 | E19: 홍천 | F19: 010-8918-5923 | G19: 장애 당사자 | I19: 남 | J19: 시각 | K19: 심한 | L19: 수급자 | M19: 신청 | R19: 텍스트 음성 변환장치(TTS) 보조기기 안내 및 지원 가능 여부 | S19: 장애인 보조기기 교부사업에서 신청 가능한 TTS소프트웨어 안내드림. | T19: 양하나
B20: =ROW()-8 -> 12 | C20: 46049 | D20: 권송자 | F20: 010-7240-8085 | G20: 장애 당사자 | R20: 의족 수리 관련 문의 | S20: 재활병원 내 의족 수리기사님과 통화후 연계함. | T20: 심채연
B21: =ROW()-8 -> 13 | C21: 46049 | E21: 철원군 보건소 cbs팀 | F21: 033-450-4023 | G21: 시군구(및 읍면동) 담당자 | R21: 보행차(zeen) 보조기기 대여 및 지원 가능 여부 | S21: 현재 센터 내에서는 zeen과 관련한 보조기기는 보유하지 않아 대여가 불가능하다는 것을 안내드림. | T21: 심채연
B22: =ROW()-8 -> 14 | C22: 46051 | D22: 홍수복 | E22: 원주 | F22: 010-5072-5667 | G22: 보호자 및 지인 | H22: 김승아 | I22: 여 | J22: 뇌병변 | K22: 심한 | R22: 숟가락 보조기기 제작 의뢰 | S22: 2월 중 방문예정 | T22: 송근필
B23: =ROW()-8 -> 15 | C23: 46055 | D23: 이상기 | F23: 010-9066-0275 | G23: 장애 당사자 | O23: 개조 및 제작 | R23: 랩보드 제작 요청 문의 | S23: 랩보드 제작 요청하여 담당자에게 전달드린다고 함. | T23: 심채연
B24: =ROW()-8 -> 16 | C24: 46057 | D24: 김승겸 | E24: 속초시장애인체육회 | F24: 010-2747-6091 | G24: 유관기관 종사자 | O24: 개조 및 제작 | R24: 보치아선수 보조기기 제작 의뢰 | S24: 2월 중 속초 방문 일정 잡기로함 | T24: 송근필
B25: =ROW()-8 -> 17 | C25: 46057 | E25: 원주 | F25: 010-4012-8805 | G25: 보호자 및 지인 | H25: 권수미 | I25: 여 | O25: 대여 | R25: 사용하고 있던 수동휠체어가 망가져 급하게 대여요청 문의 | S25: 대여 담당자에게 정보전달 | T25: 송근필
B26: =ROW()-8 -> 18 | C26: 46057 | E26: 원주 | F26: 010-6722-5055 | G26: 보호자 및 지인 | H26: 박진수 | I26: 남 | J26: 뇌병변 | K26: 심한 | M26: 급여 정보 | R26: 자세보조용구 (서기형) 급여결정 통지서 받은 후 지원 받는 절차 안내 문의 | S26: 건강보험공단에 등록되어 있는 제조업체(에이블라이프) 연락처 안내 | T26: 송근필
B27: =ROW()-8 -> 19 | C27: 46062 | F27: 010-6739-9753 | G27: 보호자 및 지인 | H27: 이재학 | I27: 남 | M27: 급여 정보 | R27: 목욕용 휠체어 급여정보 및 신청 기관 문의 | S27: 건강보험납입, 장기요양 대상자에 해당되어 복지용구 급여 신청을 위해 건강보험공단으로 문의할 수 있도록 안내드림. | T27: 양하나
B28: =ROW()-8 -> 20 | C28: 46062 | E28: 춘천 | F28: 010-6381-1565 | G28: 보호자 및 지인 | O28: 수리 | R28: 캐롯카시트 끈조질 및 길이 연장 가능한지에 대한 문의를 주셨음. | S28: 재활병원 어린이병동에 계시다가 하셔서 카시트를 직접 가지고 방문하시면 수리 여부 가능한지 안내해드리기로 하였음. | T28: 이창하
B29: =ROW()-8 -> 21 | C29: 46063 | D29: 조지영 | E29: 강릉 | F29: 010-9057-2102 | G29: 장애 당사자 | O29: 대여 | R29: 전동휠체어 대여 문의 | S29: 전동휠체어 대여 가능여부에 대해 불가능하다는 답변을 드렸고, 구매 정보에 대한 안내 드렸음. | T29: 심채연
B30: =ROW()-8 -> 22 | C30: 46063 | D30: 권수미 | E30: 원주 | F30: 010-4012-8805 | G30: 보호자 및 지인 | O30: 대여 | R30: 오터 목욕의자 대여 문의 | S30: 대상자 키의 맞는 목욕의자 찾게 되면 다시 재 연락드린다고 안내 드렸음. | T30: 심채연
B31: =ROW()-8 -> 23 | C31: 46065 | F31: 010-3935-8224 | G31: 보호자 및 지인 | O31: 대여 | R31: 대여 사업을 언제부터 진행하는 지 문의를 주셨음. | S31: 3월달부터 진행한다고 안내해드렸음. | T31: 이창하
B32: =ROW()-8 -> 24 | C32: 46077 | E32: 동해 | F32: 010-9074-5441 | G32: 보호자 및 지인 | R32: 맞춤제작 휠체어,높낮이 조절 책상 지원 또는 구매방법에 대하여 알고 싶다고 문의를 주셨음. | S32: 푸르메재단 민간지원사업 안내해드렸음. | T32: 이창하
B33: =ROW()-8 -> 25 | C33: 46078 | D33: 이현준 | E33: 춘천 | F33: 010-9496-7411 | G33: 장애 당사자 | Q33: 보조기기 서비스 | R33: 장애진단이 없음에도 지원받을 수 있는 보조기기 서비스에 대하여 문의주셨음. | S33: 장애진단과 장기요양으로 등록되어 있지 않기 때문에 보조기기센터 이용하는데 어려움이 있으며, 장애등록서비스 안내해드림. | T33: 심채연
B34: =ROW()-8 -> 26 | C34: 46078 | D34: 화천군 보건의료센터 | E34: 화천군 | F34: 033-440-2818 | G34: 유관기관 종사자 | O34: 구입 | R34: 일반수동휠체어 구입 관련 문의주셨음. | S34: 장애인보조기기 급여사업에 대한 정보를 안내드렸음. | T34: 심채연
B35: =ROW()-8 -> 27 | C35: 46080 | E35: 춘천시 | F35: 010-9000-7050 | G35: 보호자 및 지인 | O35: 대여 | R35: 휠체어 대여 관련 문의주셨음 | S35: 장기요양 등록 확인 후 대여 안내드리고 하였음. | T35: 심채연
B36: =ROW()-8 -> 28 | C36: 46080 | D36: 방시우 | E36: 영월군 | F36: 010-8711-9062 | G36: 보호자 및 지인 | I36: 남 | J36: 뇌병변 | K36: 중증 | L36: 일반 | O36: 대여 | R36: 포니워커 대여 관련 문의주셨음. | S36: 확인 후 다시 연락드리고 안내드렸음. | T36: 심채연
B37: =ROW()-8 -> 29 | C37: 46084 | D37: 강장복 화천CBS | E37: 화천군 | F37: 033-441-2491 | G37: 유관기관 종사자 | Q37: 견학 | R37: 보조기기센터 견학관련 문의 | S37: 보조기기 견학 서비스 정보안내 및 일정조율 4월 9일 견학요청 예정 | T37: 송근필
B38: =ROW()-8 -> 30 | C38: 46090 | D38: 장영자 | E38: 철원군 | F38: 010-2773-0466 | G38: 장애 당사자 | I38: 여 | J38: 지체 | K38: 중증 | L38: 일반 | O38: 대여 | R38: 보조기기 신청 관련 문의 | S38: 노인장기요양보험복지용구급여사업 신청 전 롤레이터 사용을 원하신다구 하셔서 대여 서비스 안내드림. 강원 철원군 갈말읍 명성로179번길 10 나동 106호 | T38: 심채연
B39: =ROW()-8 -> 31 | C39: 46091 | D39: 이한순 | E39: 영월군 | F39: 010-9441-0205 | G39: 장애 당사자 | I39: 남 | J39: 지체 | K39: 중증 | L39: 수급자 | R39: 자동차 개조,장애등록이 되어 있는데 운전면허증 갱신일이 다 되어가는데 운전면허가 바로 취소가 되는지,지체장애를 가지고 있는 지원받을 수 있는 지원사업이 있는지. | S39: 국립재활원에 문의를 드렸고 운전면허증은 자동으로 취소가 될것으로 안내해드렸음. 기초생활수급자이셔서 교부사업 신청에 대해서 안내해드렸음. | T39: 이창하
B40: =ROW()-8 -> 32 | C40: 46092 | D40: 임승택 | E40: 원주시 | F40: 010-3470-6566 | G40: 장애 당사자 | I40: 남 | J40: 지체 | K40: 경증 | R40: 타이핑을 하는데 필요한 보조기구에 대한 정보제공이 필요함 | S40: 출장 일정 잡은 후 환경 평가하면서 함께 필요한 보조기구 설명드리기로 하였음. 원주시 혁신로 224번길 604동 903호 | T40: 심채연
B41: =ROW()-8 -> 33 | C41: 46094 | E41: 정선군 | F41: 010-2317-5397 | G41: 보호자 및 지인 | I41: 여 | J41: 복합(지체, 청각) | K41: 중증 | L41: 수급자 | M41: 급여 정보 | R41: 청각 및 지체에 관련된 공적 지원사업에 대한 정보제공이 필요함. | S41: 교부사업 및 행정복지센터에서 전동휠체어 신청받는 방법에 대해 안내해드림. | T41: 심채연
B42: =ROW()-8 -> 34 | C42: 46099 | E42: 춘천시 | F42: 010-8684-1476 | G42: 보호자 및 지인 | I42: 남 | J42: 지체 | K42: 중증 | Q42: 교육 | R42: 휠마스터 교육 관련 문의 | S42: 보조기기센터 자체에서 휠마스터 교육을 하는지 문의주셔서 진행하지 않는다고 답변 드림. 또한 장애인 일자리 관련 문의도 함께 주셔서 춘천시청장애인복지과로 연결해드림. | T42: 심채연
...

Sheet 2025
B1: <안내 사항> 1. 향후 각 보조기기센터 콜센터 상담일지 내용 취합 시 개인정보보호법 해당되는 의뢰인 성명, 의뢰인 연락처에 해당되는 항목은 제외하여 회신 * 의뢰인 성명, 의뢰인 연락처 : 개인을 알아볼 수 있는 정보(해당 정보만으로는 특정 개인을 알아볼 수 없더라도 다른 정보와 쉽게 결합하여 알아볼 수 있는 것을 포함함) 2. 엑셀시트 항목 중 진한글씨항목(연번, 상담일, 의뢰외 유형, 상담내용(질문유형, 질문내용, 답볍))은 필수항목이므로 반드시 입력, 이외 나머지는 선택사항임 3. 상담내용 작성 시, 반드시 질문유형(공적급여, 민간급여, 보조기기, 사례연계, 기타)에 한가지는 입력 후 질문내용 및 답변 입력 필요
C2: 보호자 및 지인
B4: 일반정보 | M4: 상담내용 | T4: 상담자
B5: 연번 | C5: 상담일 | D5: 의뢰인 성명 | E5: 의뢰인 지역 또는 소속 | F5: 의뢰인 연락처 | G5: 의뢰인 유형 | H5: 대상자 성명 | I5: 대상자 성별 | J5: 대상자 장애유형 | K5: 대상자 장애정도 | L5: 대상자 경제상황 | M5: 질문 유형 | R5: 질문내용 | S5: 답변 (상담에 따른 조치사항 등)
M6: 공적급여 | N6: 민간급여 | O6: 보조기기 | P6: 사례연계 | Q6: 기타
M7: =COUNTA(M9:M283) -> 45 | N7: =COUNTA(N9:N283) -> 8 | O7: =COUNTA(O9:O283) -> 109 | P7: =COUNTA(P9:P283) -> 1 | Q7: =COUNTA(Q9:Q283) -> 5
B8: =COUNTA(B9:B283) -> 185 | C8: =COUNTA(C9:C283) -> 172 | G8: =COUNTA(G9:G283) -> 172 | M8: =SUM(M7:Q7) -> 168
B9: =ROW()-8 -> 1 | C9: 45663 | D9: 한장금 | E9: 인제 | F9: 010-5378-5000 | G9: 장애 당사자 | H9: 한장금 | I9: 남 | J9: 시각 | K9: 심한 | L9: 일반 | O9: 구입 | R9: 리보3S 지원 문의 | S9: 정보통신보조기기보급사업 관련 내용 안내 | T9: 송근필
B10: =ROW()-8 -> 2 | C10: 45663 | D10: 김정진 | E10: 홍천 | F10: 010-7525-2404 | G10: 보호자 및 지인 | H10: 김종은 | I10: 남 | J10: 지체 | K10: 심한 | L10: 일반 | O10: 개조 및 제작 | R10: ITDA 제작 플랫폼으로 리코더 받침대 제작 의뢰 | S10: 추후 일정조율 건으로 다시 연락드리기로 함 | T10: 송근필
B11: =ROW()-8 -> 3 | C11: 45664 | D11: 원서빈 | E11: 원주 | F11: 010-3677-7556 | G11: 보호자 및 지인 | H11: 경민성 | N11: 품목 | O11: 대여 | R11: 보완대체의사소통 보조기기(한뼘 AAC) 대여 문의 | S11: 대기명단에 추가하여 차례가 되었을 때 연락드린다고 함. | T11: 장홍민
B12: =ROW()-8 -> 4 | C12: 45665 | D12: 김인숙 | E12: 춘천 | F12: 010-7475-7161 | G12: 장애 당사자 | H12: 김인숙 | I12: 여 | J12: 지체 | K12: 심한 | L12: 수급자 | O12: 기타 | R12: 에이블라이프에 대해서 설명 부탁드립니다. | S12: 1. 에이블라이프 정보 제공 2. 노트북은 보조기기가 아니라 보조기기센터에서 지원하지 않는다고 알려드림 | T12: 김영기
B13: =ROW()-8 -> 5 | C13: 45665 | E13: 화천 | F13: 033-441-2491 | G13: 유관기관 종사자 | K13: 심하지않은 | L13: 수급자 | M13: 품목 | R13: 워커 지원사업 문의 | S13: 1. 의사 처방 후 건강보험공단 2. 주민센터 방문 장애인보조기기 교부사업(25만원 지원) 3. 주변 의료기기업체 자부담 구매 | T13: 김영기
B14: =ROW()-8 -> 6 | C14: 45667 | D14: (부) | F14: 010-4921-0992 | G14: 보호자 및 지인 | H14: 96년생 | J14: 지체 | K14: 심한 | L14: 일반 | O14: 기타 | R14: 슈마DA-7800 대여 가능 문의 | S14: 보유하고있지 않아 대체 보조기기(SS-1000) 안내 및 교부사업, 민간지원사업, 대여 사업 안내 | T14: 장홍민
B15: =ROW()-8 -> 7 | C15: 45667 | D15: 이찬섭 | E15: 춘천 | F15: 010-4941-7292 | G15: 장애 당사자 | O15: 대여 | R15: 기립기 대여 가능 날짜 문의 | S15: 2월~3월 사이 가능할 것 같다고 안내함. 대여가 가능할 때 다시 연락드린다고 함. | T15: 장홍민
B16: =ROW()-8 -> 8 | C16: 45667 | D16: 탁충열 | E16: 고성 | F16: 010-5688-2990 | G16: 장애 당사자 | H16: 탁충열 | I16: 남 | J16: 지체 | K16: 심한 | L16: 수급자 | R16: 전동침대 지원 문의 | S16: 주민센터 방문하여 장애인보조기기 교부사업 신청 가능하다고 안내해드림 | T16: 김영기
B17: =ROW()-8 -> 9 | C17: 45670 | F17: 010-9446-6777 | G17: 보호자 및 지인 | O17: 기타 | R17: 보행차 지원받을 수 있는 방법에 대해 문의 | S17: 지원사업과 대여 서비스에 대해서 안내, 장애등록과 노인장기요양등급 받는 방법에 대해서도 안내 | T17: 장홍민
B18: =ROW()-8 -> 10 | C18: 45670 | E18: 강릉 | F18: 033-660-3740 | G18: 유관기관 종사자 | M18: 품목 | R18: 욕창예방매트리스, 방석 신청 가능 장애유형에 대해 문의 | S18: 심장장애만 신청 가능하다고 답변 | T18: 장홍민
B19: =ROW()-8 -> 11 | C19: 45670 | E19: 횡성 | F19: 033-340-2167 | G19: 유관기관 종사자 | O19: 수리 | R19: 보조기기교부사업으로 받은 대화용장치 수리에 대해 문의 | S19: 센터에서는 간단한 경정비외에는 수리를 진행하지 않아 업체에 연락하여 수리 진행하면 된다고 답변함. | T19: 장홍민
B20: =ROW()-8 -> 12 | C20: 45671 | F20: 010-3465-7449 | G20: 장애 당사자 | O20: 대여 | R20: 전동휠체어 대여 가능 문의 | S20: 전동휠체어는 안전상의 이유로 대여가 불가능하다고 답변. | T20: 장홍민
B21: =ROW()-8 -> 13 | C21: 45671 | D21: 탁충열 | E21: 고성 | F21: 010-5688-2990 | G21: 장애 당사자 | H21: 탁충열 | I21: 남 | J21: 지체 | K21: 심한 | L21: 수급자 | M21: 품목 | R21: 작년에 전동휠체어를 지원 받았는데 올해 전동침대 받을 수 있는지 문의 | S21: 전동침대와 전동휠체어는 다른 사업이라 교부사업으로 전동침대 신청 가능하다고 안내함 | T21: 김영기
B22: =ROW()-8 -> 14 | C22: 45672 | D22: 안두훈 | E22: 원주 | F22: 010-7183-7948 | G22: 장애 당사자 | H22: 안두훈 | I22: 남 | J22: 뇌병변 | K22: 심한 | L22: 수급자 | Q22: 재제작 | R22: 작년에 받은 컵홀더 파손되어 재제작 가능한지 문의 | S22: 재제작 가능하며, 2월초 출장 일정 잡아서 방문하기로 함 | T22: 김영기
B23: =ROW()-8 -> 15 | C23: 45672 | D23: 삼척시청 | E23: 삼척 | F23: 033-570-3329 | G23: 시군구(및 읍면동) 담당자 | M23: 신청 | R23: 적합성 평가 의뢰한 대상자분 언제 진행이 가능한지, 결과보고서는 언제 받을 수 있는 문의 | S23: 2월 지나서 출장 가능하여 2월 2번째주는 지나야 출장이 가능할 것 같다고 답변하고, 출장 후에 2~3일 이내에 결과보고서 보낼 예정이라고 답변 | T23: 장홍민
B24: =ROW()-8 -> 16 | C24: 45674 | E24: 원주 | F24: 010-2800-1025 | G24: 보호자 및 지인 | H24: 한효리 | I24: 여 | J24: 지체 | K24: 심한 | L24: 일반 | N24: 신청 | R24: 2025 희귀난치어린이 의료비 사업 제출 서류 중 의사소견서 3개월이 지난 의사소견서로 제출이 가능한지 문의 | S24: 제출이 가능하지만 불이익이 있을수 있음을 공지함. | T24: 송근필
B25: =ROW()-8 -> 17 | C25: 45674 | E25: 춘천 | F25: 010-9261-2716 | G25: 장애 당사자 | H25: 배재현 | I25: 남 | J25: 지체 | K25: 심한 | L25: 일반 | O25: 개조 및 제작 | R25: 맞춤제작 지원 일정 조율 | S25: 일정 조율 완료 | T25: 송근필
B26: =ROW()-8 -> 18 | C26: 45679 | E26: 강릉 | F26: 033-640-1261 | G26: 교육기관 종사자 | N26: 신청 | R26: 희귀난치어린이지원사업 신청서 작성법 문의 | S26: 신청서 작성 요령 안내 | T26: 송근필
B27: =ROW()-8 -> 19 | C27: 45699 | D27: 이명호 | E27: 춘천 | F27: 010-4234-6376 | G27: 장애 당사자 | H27: 이명호 | I27: 남 | J27: 시각 | K27: 심한 | O27: 점검 | R27: 센스리더 사용중이며 현재 고장이 나서 고칠수 있는지 문의 (작년 상범선생님 담당했던 대상자) | T27: 송근필
B28: =ROW()-8 -> 20 | C28: 45700 | D28: 이다온 | E28: 춘천 | F28: 010-8454-2046 | G28: 보호자 및 지인 | H28: 이다온 | I28: 남 | J28: 뇌병변 | K28: 심한 | L28: 일반 | O28: 종류 | R28: 전동휠체어 지원사업 문의 | S28: 건강보험 보조기기 지원사업, 민간지원사업, 토도웍스 상상인 지원사업 안내 | T28: 김영기
B29: =ROW()-8 -> 21 | C29: 45700 | D29: 이정자 | E29: 원주 | F29: 033-737-5866 | G29: 유관기관 종사자 | M29: 급여 정보 | R29: 교부사업 신청 대상자분께서 리보3S 보조기기를 신청할려고 하는데 교부사업 품목에 해당이 되는지 문의 | S29: 눅음 및 재생장치에 품목에 관련 설명 및 교부사업 가이드북 배포 예정 | T29: 송근필
B30: =ROW()-8 -> 22 | C30: 45701 | F30: 010-5155-7276 | G30: 보호자 및 지인 | O30: 기타 | R30: 처방전을 받아 이너시트를 신청하려는데 어떻게 신청하는건지 문의 | S30: 국민건강보험 장애인 보조기기 급여제도에 대해 안내 | T30: 장홍민
B31: =ROW()-8 -> 23 | C31: 45702 | E31: 삼척시보건소 | F31: 033-570-4662 | G31: 유관기관 종사자 | M31: 급여 정보 | R31: 교부사업 가이드북 관련문의 | S31: 가이드북 활용법 및 교부사업 정보 안내 | T31: 송근필
B32: =ROW()-8 -> 24 | C32: 45705 | D32: 조현지 | E32: 강릉 | F32: 010-8967-1324 | G32: 장애 당사자 | H32: 조현지 | I32: 여 | J32: 지체 | K32: 심한 | O32: 대여 | R32: 이동식 리프드 대여 반납 , 맞춤 제작 (트랜스퍼보드) 가능한지 문의 | S32: 대여 담당자에게 전달, 대여 반납 받으면서 맞춤제작 상담 진행 | T32: 송근필
B33: =ROW()-8 -> 25 | C33: 45705 | D33: 이정자 | E33: 원주 | F33: 033-737-5866 | G33: 유관기관 종사자
B34: =ROW()-8 -> 26 | C34: 45706 | F34: 010-4717-7558 | G34: 보호자 및 지인 | M34: 품목 | R34: 욕창예방매트리스 신청 방법에 대해 문의 | S34: 국민건강보험 급여제품 사업에 대해 안내 | T34: 장홍민
B35: =ROW()-8 -> 27 | C35: 45706 | D35: 소연정 | E35: 인제 | F35: 010-5496-9998 | G35: 유관기관 종사자 | J35: 시각 | O35: 대여 | R35: 이용자분중에 시각장애를 가지고 계신 이용자분이 계심. 책마루2 보조기기대여요청하셨음. | S35: 대여 담당자에게 전달 | T35: 이창하
B36: =ROW()-8 -> 28 | C36: 45706 | D36: 김용숙 | E36: 원주 | F36: 010-6806-5415 | G36: 보호자 및 지인 | J36: 지체 | M36: 품목 | O36: 구입 | R36: 보호자 자녀분꼐서 전동침대 대여에 대하여 문의를 주셨음. | S36: 대여기간이 너무 짧아 대여는 원치 않으셨고 의료기기 판매점을 통하여 구입가능하다고 안내해드렸음. | T36: 이창하
B37: =ROW()-8 -> 29 | C37: 45706 | D37: 행정복지센터 | E37: 원주 | F37: 033-737-5866 | G37: 유관기관 종사자 | M37: 내구연한 | R37: 24년 정보통신보조기기보급사업으로 데이지플레이어를 지원 받았으며, 25년도에 동일한 품목으로 교부사업에서 지원받을 수 있는지 문의 | S37: 교부사업 지침상 타 교부사업에서 지원받은 품목 내구연한이 경과되지 않았으면 신청 불가능 | T37: 송근필
B38: =ROW()-8 -> 30 | C38: 45706 | D38: 김종웅 | E38: 원주 | F38: 010-9058-3960 | G38: 장애 당사자 | H38: 김종웅 | I38: 남 | J38: 시각 | K38: 중증 | L38: 수급자 | M38: 신청 | R38: 시각장애인이 사용할수 있는 보조기기 지원 문의 | S38: 정보통신보조기기 보급사업, 장애인보조기기 교부사업 안내 문자판독기에 관련 상담 진행 | T38: 송근필
B39: =ROW()-8 -> 31 | C39: 45706 | E39: 춘천 | F39: 033-255-3482 | G39: 유관기관 종사자 | O39: 기타 | R39: 한쪽시각장애인 대상자가 지원받을 수 있는 지원사업이나 보조기기에 대해 문의 | S39: 정보통신보조기기 보급사업 안내, 보조기기의 경우에는 대상자의 욕구에 따라 달라져 상담이 필요하다고 안내함 | T39: 장홍민
B40: =ROW()-8 -> 32 | C40: 45707 | D40: 권송자 | E40: 춘천 | F40: 010-7240-8085 | G40: 장애 당사자 | H40: 권송자 | I40: 여 | J40: 지체 | K40: 중증 | L40: 일반 | O40: 점검 | R40: 21년 통합돌봄 지원 대상자: 전동침대 높낮이 조절 부분이 고장이 나서 A/s 문의 | S40: 확인 후 다시 연락드리기로 함 | T40: 송근필
B41: =ROW()-8 -> 33 | C41: 45707 | F41: 010-8790-8064 | G41: 보호자 및 지인 | M41: 품목 | O41: 구입 | R41: 기초생활수급잦이고 전동스쿠터 구입에 대한 문의를 주셨음. | S41: 건강보험공단 급여제품 안내 책자 참고하여 전동스쿠터 가격과 지원금액 안내해드렸음. | T41: 이창하
...

Sheet 2025DB
B1: 월 | C1: 건수 | E1: 의뢰인 유형 | F1: 건수 | G1: 공적급여 | H1: 건수 | I1: 민간급여 | J1: 건수 | K1: 보조기기 | L1: 건수 | M1: 사례연계 | N1: 건수 | O1: 기타 | P1: 건수
B2: 1월 | C2: =COUNTIFS('2025'!$C$9:$C$229,">=2025-01-01",'2025'!$C$9:$C$229,"<=2025-1-31") -> 18 | E2: 장애 당사자 | F2: =COUNTIF('2025'!$G$9:$G$119,E2) -> 28 | G2: 급여정보 | I2: 급여정보 | K2: 구입 | M2: 사례관리 서비스 요청 | O2: 기타
B3: 2월 | C3: =COUNTIFS('2025'!$C$9:$C$229,">=2025-01-01",'2025'!$C$9:$C$229,"<=2025-1-31") -> 18 | E3: 보호자 및 지인 | F3: =COUNTIF('2025'!$G$9:$G$119,E3) -> 41 | G3: 신청 | I3: 신청 | K3: 가격 | M3: 타 센터 및 기관 사례 연계
B4: 3월 | C4: =COUNTIFS('2025'!$C$9:$C$229,">=2025-01-01",'2025'!$C$9:$C$229,"<=2025-1-31") -> 18 | E4: 시군구(및 읍면동) 담당자 | F4: =COUNTIF('2025'!$G$9:$G$119,E4) -> 10 | G4: 지원범위 | I4: 지원범위 | K4: 기능 | M4: 기타
B5: 4월 | C5: =COUNTIFS('2025'!$C$9:$C$229,">=2025-01-01",'2025'!$C$9:$C$229,"<=2025-1-31") -> 18 | E5: 유관기관 종사자 | F5: =COUNTIF('2025'!$G$9:$G$119,E5) -> 29 | G5: 품목 | I5: 품목 | K5: 종류
B6: 5월 | C6: =COUNTIFS('2025'!$C$9:$C$229,">=2025-01-01",'2025'!$C$9:$C$229,"<=2025-1-31") -> 18 | E6: 교육기관 종사자 | F6: =COUNTIF('2025'!$G$9:$G$119,E6) -> 3 | G6: 내구연한 | I6: 기타 | K6: 명칭
B7: 6월 | C7: =COUNTIFS('2025'!$C$9:$C$229,">=2025-01-01",'2025'!$C$9:$C$229,"<=2025-1-31") -> 18 | E7: 기타 | F7: =COUNTIF('2025'!$G$9:$G$119,E7) -> 0 | G7: 기타 | K7: 대여
B8: 7월 | C8: =COUNTIFS('2025'!$C$9:$C$229,">=2025-01-01",'2025'!$C$9:$C$229,"<=2025-1-31") -> 18 | E8: 합계 | F8: =SUM(F2:F7) -> 111 | G8: 합계 | H8: =SUM(H2:H7) -> 0 | K8: 개조 및 제작
B9: 8월 | C9: =COUNTIFS('2025'!$C$9:$C$229,">=2025-01-01",'2025'!$C$9:$C$229,"<=2025-1-31") -> 18 | F9: =F4/118 -> 0.084745763 | K9: 세척
B10: 9월 | C10: =COUNTIFS('2025'!$C$9:$C$229,">=2025-01-01",'2025'!$C$9:$C$229,"<=2025-1-31") -> 18 | K10: 점검
B11: 10월 | C11: =COUNTIFS('2025'!$C$9:$C$229,">=2025-01-01",'2025'!$C$9:$C$229,"<=2025-1-31") -> 18 | K11: 수리
B12: 11월 | C12: =COUNTIFS('2025'!$C$9:$C$229,">=2025-01-01",'2025'!$C$9:$C$229,"<=2025-1-31") -> 18 | K12: 재사용
B13: 12월 | C13: =COUNTIFS('2025'!$C$9:$C$229,">=2025-01-01",'2025'!$C$9:$C$229,"<=2025-1-31") -> 18 | K13: 기타
B14: 합계 | C14: =SUM(C2:C13) -> 216
I23: 95
I24: 20 | J24: =I24/I23 -> 0.21052632

Sheet 2024
B1: <안내 사항> 1. 향후 각 보조기기센터 콜센터 상담일지 내용 취합 시 개인정보보호법 해당되는 의뢰인 성명, 의뢰인 연락처에 해당되는 항목은 제외하여 회신 * 의뢰인 성명, 의뢰인 연락처 : 개인을 알아볼 수 있는 정보(해당 정보만으로는 특정 개인을 알아볼 수 없더라도 다른 정보와 쉽게 결합하여 알아볼 수 있는 것을 포함함) 2. 엑셀시트 항목 중 진한글씨항목(연번, 상담일, 의뢰외 유형, 상담내용(질문유형, 질문내용, 답볍))은 필수항목이므로 반드시 입력, 이외 나머지는 선택사항임 3. 상담내용 작성 시, 반드시 질문유형(공적급여, 민간급여, 보조기기, 사례연계, 기타)에 한가지는 입력 후 질문내용 및 답변 입력 필요
C2: 보호자 및 지인
B4: 일반정보 | M4: 상담내용 | T4: 상담자
B5: 연번 | C5: 상담일 | D5: 의뢰인 성명 | E5: 의뢰인 지역 또는 소속 | F5: 의뢰인 연락처 | G5: 의뢰인 유형 | H5: 대상자 성명 | I5: 대상자 성별 | J5: 대상자 장애유형 | K5: 대상자 장애정도 | L5: 대상자 경제상황 | M5: 질문 유형 | R5: 질문내용 | S5: 답변 (상담에 따른 조치사항 등)
M6: 공적급여 | N6: 민간급여 | O6: 보조기기 | P6: 사례연계 | Q6: 기타
M7: =COUNTA(M9:M283) -> 60 | N7: =COUNTA(N9:N283) -> 8 | O7: =COUNTA(O9:O283) -> 66 | P7: =COUNTA(P9:P283) -> 0 | Q7: =COUNTA(Q9:Q283) -> 17
B8: =COUNTA(B9:B283) -> 185 | C8: =COUNTA(C9:C283) -> 160 | G8: =COUNTA(G9:G283) -> 157 | M8: =SUM(M7:Q7) -> 151
B9: =ROW()-8 -> 1 | C9: 45296 | E9: 동해시청 복지과 | G9: 시군구(및 읍면동) 담당자 | M9: 품목 | R9: 의료급여 욕창예방방석 장애유형은 지체, 뇌병변인데 교부사업과 치이 | S9: 교부사업은 심장장애인 경우 지원 가능하다고 답변 | T9: 정소영
B10: =ROW()-8 -> 2 | C10: 45296 | D10: 이미정 | E10: 강릉 | F10: 010-4806-2025 | G10: 장애 당사자 | H10: 이미정 | I10: 여 | J10: 지체 | K10: 중증 | L10: 수급자 | M10: 품목 | R10: 휠체어담요 사이즈교환 및 교부사업 재신청 가능 여부 | S10: 사이즈교환은 불가능하고 내구연한 2년 제품으로 2026년 재신청 가능하다고 답변 | T10: 장홍민
B11: =ROW()-8 -> 3 | C11: 45301 | F11: 010-4741-1555 | G11: 보호자 및 지인 | Q11: 0 | R11: 의료용 침대 매트리스 소독 여부 문의 | S11: 보조기기 서비스에 해당 되지 않음을 안내 | T11: 정소영
B12: =ROW()-8 -> 4 | C12: 45306 | E12: 춘천 | G12: 장애 당사자 | I12: 남 | J12: 지체 | K12: 중증 | L12: 수급자 | M12: 급여 정보 | R12: 보조기기를 신청하고 싶은데 어떻게 해야하는지 문의 | S12: 의료급여, 교부사업 안내 | T12: 정소영
B13: =ROW()-8 -> 5 | C13: 45313 | E13: 활동지원사 | G13: 보호자 및 지인 | I13: 남 | J13: 뇌병변 | L13: 수급자 | M13: 급여 정보 | R13: 보행차 지원을 받고 싶은데 어떻게 해야 하는지 문의 | S13: 교부사업 안내 | T13: 정소영
B14: =ROW()-8 -> 6 | C14: 45316 | E14: 강릉 | F14: 010-2301-3309 | G14: 보호자 및 지인 | I14: 남 | J14: 지체 | K14: 중증 | L14: 차상위 | M14: 급여 정보 | R14: 장애인보조기기 교부사업 정보 문의 | S14: 교부사업 안내 | T14: 송근필
B15: =ROW()-8 -> 7 | C15: 45322 | D15: 김명옥 | E15: 홍천군 | F15: 010-6725-3888 | G15: 장애 당사자 | I15: 여 | J15: 지체 | K15: 중증 | O15: 기타 | R15: 차에 실을 만한 가벼운 휠체어 체험 희망 | S15: 2월 15일 10~11시 내방 예정 | T15: 정소영
B16: =ROW()-8 -> 8 | C16: 45324 | F16: 010-3367-7864 | G16: 보호자 및 지인 | L16: 수급자 | M16: 신청 | R16: 전동휠체어 신청 절차 중 처방전 관련 문의 | S16: 처방전 발생 밥법 안내 | T16: 정소영
B17: =ROW()-8 -> 9 | C17: 45328 | E17: 태백시 행정복지센터 | G17: 시군구(및 읍면동) 담당자 | L17: 수급자 | M17: 품목 | R17: 어르신들이 끌고다니다가 앉아있을수도 있고 물건도 실을 수 있는 기기 이름 | S17: 보행차 품목 안내(좌석형, 탁자형 등) | T17: 정소영
B18: =ROW()-8 -> 10 | C18: 45336 | D18: 박병모 | E18: 원주 | F18: 010-6762-8582 | G18: 보호자 및 지인 | O18: 대여 | R18: 2019년생 원주 거주 심한 뇌병변 장애 3번 염색체 이상 희귀난치성질환 키 110cm, 체중 14kg 캐롯카시트, 피더시트 대여 문의 | S18: 대여 담당자 연결해드리기로 함 | T18: 김영기
B19: =ROW()-8 -> 11 | C19: 45337 | G19: 보호자 및 지인 | J19: 국가유공자 5급 | M19: 급여 정보 | R19: 보훈처에서 휠체어 지원이 안된다고 하는데 지원 받을 수 있는 방법 | S19: 의사 처방전 요청하여 건보공단 신청 여부 확인 안내 | T19: 정소영
B20: =ROW()-8 -> 12 | C20: 45337 | E20: 춘천 | G20: 보호자 및 지인 | J20: 지체 | K20: 중증 | M20: 급여 정보 | R20: 전동침대 지원 방법, 휠체어 지원 방법 문의 | S20: 휠체어 건보급여 안내, 전동침대 대여 방법 안내 | T20: 정소영
B21: =ROW()-8 -> 13 | C21: 45341 | D21: 박관순 | E21: 동해 | F21: 010-9324-2502 | G21: 장애 당사자 | J21: 뇌병변 | L21: 수급자 | M21: 급여 정보 | R21: 보행차 지원 | S21: 교부사업 안내 | T21: 정소영
B22: =ROW()-8 -> 14 | C22: 45348 | F22: 010-8619-7890 | G22: 장애 당사자 | J22: 지체 | L22: 일반 | M22: 신청 | R22: 천수손상(하지마비) 욕창예방 방석 지원 신청 문의 | S22: 건강보험급여 신청 안내 | T22: 정소영
B23: =ROW()-8 -> 15 | C23: 45348 | G23: 보호자 및 지인 | J23: 장기요양 | L23: 일반 | M23: 신청 | R23: 요양등급 3급, 목욕의자 구매 또는 지원 방법 | S23: 노인장기요양 복지용구지원사업 안내, 강릉 근처 의료기기상사 안내 | T23: 정소영
B24: =ROW()-8 -> 16 | C24: 45351 | D24: 박성훈 | E24: 춘천 | F24: 010-5309-5963 | G24: 유관기관 종사자 | H24: 서성자 | I24: 여 | J24: 지체 | O24: 대여 | R24: 수동휠체어 대여, 재사용 지원 가능 문의 | S24: 대상자 연락을 통해 수동 휠체어 대여 진행 예정 | T24: 장홍민
B25: =ROW()-8 -> 17 | C25: 45355 | D25: 정민지 | E25: 춘천 | F25: 033-250-4295 | G25: 시군구(및 읍면동) 담당자 | H25: 김정자 | I25: 여 | J25: 지체 | L25: 차상위 | M25: 품목 | R25: 교정용 신발 관련 지원방법 및 교부사업으로 지원가능한지 문의 | S25: 건강보험급여 안내 및 신청방법 안내 | T25: 박상범
B26: =ROW()-8 -> 18 | C26: 45356 | D26: 허지혜 | F26: 010-3330-6352 | G26: 보호자 및 지인 | H26: 허고운 | I26: 남 | J26: 지체 | K26: 중증 | O26: 대여 | R26: 안구마우스 대여 및 사용법 문의 | S26: 현재 보호자의 집으로 거주지를 옮겨 경기도에 거주 중, 이에 경기도 센터로 안내 및 연결함 | T26: 박상범
B27: =ROW()-8 -> 19 | C27: 45358 | E27: 동해해솔학교 | G27: 교육기관 종사자 | N27: 급여정보 | R27: SPC 민간지원사업 관련 문의 | S27: 추 후 신청 보조기기 문의 연락에 대한 답변 예정 | T27: 장홍민
B28: =ROW()-8 -> 20 | C28: 45359 | E28: 고성군청 | F28: 033-680-3444 | G28: 시군구(및 읍면동) 담당자 | M28: 기타 | R28: 교부 확인 방법 문의 | S28: 2024년 장애인복지사업 안내 책자 내용 안내 | T28: 정소영
B29: =ROW()-8 -> 21 | C29: 45365 | E29: 속초시 노학동 주민센터 | G29: 시군구(및 읍면동) 담당자 | J29: 지체 | L29: 수급자 | M29: 품목 | R29: 지지대 및 손잡이 정의 | S29: 안전손잡이 설명 | T29: 정소영
B30: =ROW()-8 -> 22 | C30: 45366 | E30: 춘장복 | F30: 033-262-0035 | G30: 유관기관 종사자 | J30: 지체 | Q30: 의지보조기 | R30: 의지보조기 맞춤 제작 상담 받을 수 있는 곳 문의 | S30: 춘천관내 의지보조기 상사 안내 | T30: 정소영
B31: =ROW()-8 -> 23 | C31: 45370 | F31: 010-3543-3364 | O31: 대여 | R31: 손떨림이 심하셔서 식사 보조기기 대여 하고 싶어하심. | S31: 장애등급, 노인장기요양등급 여부 확인 후 다시 전화 주시기로 함. 기기 구매 방법 안내 | T31: 정소영
B32: =ROW()-8 -> 24 | C32: 45370 | E32: 고성군청 | G32: 시군구(및 읍면동) 담당자 | M32: 지원범위 | R32: 품목 3개 신청 가능 여부, 안전손잡이 지원 개수 | S32: 지원기준금액 합계 200만원 한도 내 3개 가능, 안전손잡이 경우 환경 및 용도에 따라 담당자가 지정 | T32: 정소영
B33: =ROW()-8 -> 25 | C33: 45371 | E33: 철원군 동송읍 행정복지센터 | F33: 033-450-5623 | G33: 시군구(및 읍면동) 담당자 | Q33: 보조기 | R33: 발목이 떨어지지 않게 고정해주는 기기 이름과 지원사업 문의 | S33: 보조기 종류로 의료급여사업 안내 | T33: 정소영
B34: =ROW()-8 -> 26 | C34: 45379 | D34: 박성수 | E34: 강원명진학교 | F34: 010-3479-9870 | G34: 교육기관 종사자 | N34: 지원범위 | R34: 2024 따뜻한동행 첨단보조기기 지원사업 문의 | S34: 지원연령, 지원기기 정보 답변 | T34: 장홍민
B35: =ROW()-8 -> 27 | C35: 45380 | D35: 조연경 | E35: 강원특수교육지원센터 | G35: 교육기관 종사자 | O35: 대여 | R35: 경제상황이 건강보험 가입자인 학생이 지원 받을 수 있는 사업 문의 | S35: 대여 및 민간지원사업 안내, 담당자 안내 | T35: 정소영
B36: =ROW()-8 -> 28 | C36: 45380 | G36: 보호자 및 지인 | O36: 대여 | R36: 안구마우스 대여 문의(서울시 거주) | S36: 서울시 보조기기센터 소개 및 절차 안내 | T36: 정소영
B37: =ROW()-8 -> 29 | C37: 45383 | E37: 원주시 흥업면 행정복지센터 | G37: 시군구(및 읍면동) 담당자 | Q37: 0 | R37: 전동침대 교부 받은 이후 요양병원에 들어가시면서 전동침대를 어떻게 처리 해야하는 지 문의 | S37: 기증 및 재사용 등 활용 방안 안내 | T37: 정소영
B38: =ROW()-8 -> 30 | C38: 45384 | E38: 원주시 천사들의집 | F38: 010-3816-0116 | G38: 유관기관 종사자 | J38: 지적 | K38: 중증 | L38: 일반 | O38: 구입 | R38: 바디서포트 구매 문의, 센터 기관방문 및 홍보, 상담 요청 매주 월요일 10이후 가능 | S38: 건보급여사업 절차 안내, 팀회의 후 연락드리기로 함 | T38: 정소영
B39: =ROW()-8 -> 31 | C39: 45386 | E39: 영월군 종합상담소 | F39: 033-374-7098 | G39: 유관기관 종사자 | J39: 뇌병변 | L39: 수급자 | M39: 급여 정보 | R39: 보행차 지원 사업 문의 | S39: 교부사업, 의료급여사업 안내 | T39: 정소영
B40: =ROW()-8 -> 32 | C40: 45398 | D40: 김희진 | G40: 장애 당사자 | J40: 시각 | K40: 중증 | L40: 수급자 | O40: 대여 | R40: 한소네6, 센스원베이직 대여 문의 | S40: 담당자 자리 비움으로 메신저 전달 | T40: 정소영
B41: =ROW()-8 -> 33 | C41: 45398 | D41: 황태현 | G41: 장애 당사자 | J41: 시각 | K41: 중증 | O41: 대여 | R41: 한소네6 대여 문의 | S41: 담당자 자리 비움으로 메신저 전달 | T41: 정소영
...

Sheet 2024DB
B1: 월 | C1: 건수 | E1: 의뢰인 유형 | F1: 건수 | G1: 공적급여 | H1: 건수 | I1: 민간급여 | J1: 건수 | K1: 보조기기 | L1: 건수 | M1: 사례연계 | N1: 건수 | O1: 기타 | P1: 건수
B2: 1월 | C2: =COUNTIFS('2024'!$C$9:$C$229,">=2024-01-01",'2024'!$C$9:$C$229,"<=2024-1-31") -> 7 | E2: 장애 당사자 | F2: =COUNTIF('2024'!$G$9:$G$119,E2) -> 20 | G2: 급여정보 | I2: 급여정보 | K2: 구입 | M2: 사례관리 서비스 요청 | O2: 기타
B3: 2월 | C3: =COUNTIFS('2024'!$C$9:$C$229,">=2024-02-01",'2024'!$C$9:$C$229,"<=2024-2-29") -> 9 | E3: 보호자 및 지인 | F3: =COUNTIF('2024'!$G$9:$G$119,E3) -> 43 | G3: 신청 | I3: 신청 | K3: 가격 | M3: 타 센터 및 기관 사례 연계
B4: 3월 | C4: =COUNTIFS('2024'!$C$9:$C$229,">=2024-03-01",'2024'!$C$9:$C$229,"<=2024-3-31") -> 12 | E4: 시군구(및 읍면동) 담당자 | F4: =COUNTIF('2024'!$G$9:$G$119,E4) -> 20 | G4: 지원범위 | I4: 지원범위 | K4: 기능 | M4: 기타
B5: 4월 | C5: =COUNTIFS('2024'!$C$9:$C$229,">=2024-04-01",'2024'!$C$9:$C$229,"<=2024-4-30") -> 21 | E5: 유관기관 종사자 | F5: =COUNTIF('2024'!$G$9:$G$119,E5) -> 14 | G5: 품목 | I5: 품목 | K5: 종류
B6: 5월 | C6: =COUNTIFS('2024'!$C$9:$C$229,">=2024-05-01",'2024'!$C$9:$C$229,"<=2024-5-31") -> 28 | E6: 교육기관 종사자 | F6: =COUNTIF('2024'!$G$9:$G$119,E6) -> 9 | G6: 내구연한 | I6: 기타 | K6: 명칭
B7: 6월 | C7: =COUNTIFS('2024'!$C$9:$C$229,">=2024-06-01",'2024'!$C$9:$C$229,"<=2024-6-30") -> 14 | E7: 기타 | F7: =COUNTIF('2024'!$G$9:$G$119,E7) -> 3 | G7: 기타 | K7: 대여
B8: 7월 | C8: =COUNTIFS('2024'!$C$9:$C$229,">=2024-07-01",'2024'!$C$9:$C$229,"<=2024-7-31") -> 7 | E8: 합계 | F8: =SUM(F2:F7) -> 109 | G8: 합계 | H8: =SUM(H2:H7) -> 0 | K8: 개조 및 제작
B9: 8월 | C9: =COUNTIFS('2024'!$C$9:$C$229,">=2024-08-01",'2024'!$C$9:$C$229,"<=2024-8-31") -> 8 | F9: =F4/118 -> 0.16949153 | K9: 세척
B10: 9월 | C10: =COUNTIFS('2024'!$C$9:$C$229,">=2024-09-01",'2024'!$C$9:$C$229,"<=2024-9-30") -> 12 | K10: 점검
B11: 10월 | C11: =COUNTIFS('2024'!$C$9:$C$229,">=2024-10-01",'2024'!$C$9:$C$229,"<=2024-10-31") -> 13 | K11: 수리
B12: 11월 | C12: =COUNTIFS('2024'!$C$9:$C$229,">=2024-11-01",'2024'!$C$9:$C$229,"<=2024-11-30") -> 5 | K12: 재사용
B13: 12월 | C13: =COUNTIFS('2024'!$C$9:$C$229,">=2024-12-01",'2024'!$C$9:$C$229,"<=2024-12-31") -> 24 | K13: 기타
B14: 합계 | C14: =SUM(C2:C13) -> 160
I23: 95
I24: 20 | J24: =I24/I23 -> 0.21052632
